Workbook
Name RiskAutoStopPercChange: 1.5
Name RiskCollectDistributionSamples: 2
Name RiskExcelReportsGoInNewWorkbook: TRUE
Name RiskExcelReportsToGenerate: 0
Name RiskFixedSeed: 1
Name RiskGenerateExcelReportsAtEndOfSimulation: FALSE
Name RiskHasSettings: TRUE
Name RiskMinimizeOnStart: FALSE
Name RiskMonitorConvergence: FALSE
Name RiskNumIterations: 5000
Name RiskNumSimulations: 1
Name RiskPauseOnError: FALSE
Name RiskRealTimeResults: FALSE
Name RiskReportGraphFormat: 0
Name RiskResultsUpdateFreq: 100
Name RiskRunAfterRecalcMacro: FALSE
Name RiskRunAfterSimMacro: FALSE
Name RiskRunBeforeRecalcMacro: FALSE
Name RiskRunBeforeSimMacro: FALSE
Name RiskSamplingType: 3
Name RiskShowRiskWindowAtEndOfSimulation: TRUE
Name RiskStandardRecalc: 1
Name RiskTemplateSheetName: "myTemplate"
Name RiskUpdateDisplay: FALSE
Name RiskUseDifferentSeedForEachSim: FALSE
Name RiskUseFixedSeed: FALSE
Name RiskUseMultipleCPUs: FALSE

Sheet DDR Remark
A1: : | H1: Daily Drilling Report
H3: Field: | M3: AZNS | R3: Well Name: | W3: AZNS-207 | AB3: Project: | AG3: AZNS | AL3: LTA (Day) | AQ3: 468
H4: Well Type: | M4: Development | R4: Well Shape: | W4: Vertical | AB4: Rig Name: | AG4: OEOC 208 | AL4: Actual Rig Days: | AQ4: 7.25
H5: Client: | M5: PPL | R5: Operator: | W5: MSA | AB5: Drilling Contractor: | AG5: OEOC | AL5: Report No.: | AQ5: 8
H6: Client Rep: | M6: S.Shahvali | R6: Hole Section (inch): | W6: 17-1/2" | AB6: Estimated Final Depth MD (m): | AG6: 4180 | AL6: Offshore Water Depth (m) | AQ6: -
H7: GLE-MSL (m): | M7: 3.95 | R7: RTE-MSL (m): | W7: 14.45 | AB7: GLE-RTE (m): | AG7: 10.5 | AL7: Rig Heading (°) | AQ7: -
A9: DATE | F9: Year | H9: Month | J9: Day | L9: MD (m)@ 0:00: | R9: 155 | W9: Drilling Operation manager: | AB9: P.Farzaneh | AF9: Latitude: | AI9: 3,441,012 N | AM9: Previous Casing Information
A10: Spud : | F10: 2024 | H10: Oct | J10: 15 | L10: MD (m)@ 24:00: | R10: 225 | W10: Drilling Superintendent: | AB10: A.R.Rezaei | AF10: Longitude: | AI10: 192,581 E | AM10: Size (in) | AN10: From (m) | AP10: To (m) | AQ10: Grade | AR10: Weight (#) | AU10: Thread | AV10: Shoe (TVD)m | AX10: Burst (psi) | AZ10: Collapse (psi)
A11: Report: | F11: 2024 | H11: Oct | J11: 22 | L11: MD (m)@ 6:00 AM: | R11: 310 | W11: Drilling Supervisor (Day): | AB11: A.Seifi | AF11: Northing (m): | AI11: 3472595 | AM11: 20" | AN11: Surface | AP11: 149 | AQ11: K-55 | AR11: 94 | AU11: BTC | AV11: 149 | AX11: 2110 | AZ11: 520
A12: Hole Section Strat: | F12: 2024 | H12: Oct | J12: 22 | L12: 24 hrs Drilled (m): | R12: =R10-R9 -> 70 | W12: Drilling Supervisor (Night): | AB12: A.Eyvazi | AF12: Easting(m): | AI12: 196977
A13: Moving Start Date: | F13: 2024 | H13: Sep | J13: 30 | L13: AVG. ROP (m/hrs.) | R13: =IF(ISNUMBER(R12/BA25)=TRUE,R12/BA25," ") -> 4.6666667 | W13: Well Site Drilling Engineering: | AB13: - | AF13: KOP #1: | AI13: -
A14: MW (PCF): | J14: 70 | L14: RT - WH (m): | R14: 12 | W14: Well Site Geologist: | AB14: Esmaeili/Gholipur | AF14: KOP #2: | AI14: -
A15: FIT Depth (MD/TVD) /EMW (PCF): | M15: Section Start Depth MD(m): | R15: 151 | W15: Tool Pusher Day / Night : | AB15: R.Harati/R.Hezarian | AF15: Formation: | AI15: Aghajari
A16: Summary of Activities in Last 24:00 hours:
A17: Cont. Drlg 17-1/2" HS to 165m, POOH to surface, Obs. 2 No. of NZL Seat area washed out, RIH w/ 17-1/2" Drlg BHA to BTM, Commence Drlg 17-1/2" HS to 225m.
A19: Operation Forecast for next 24 hours:
A20: Cont. Drlg 17-1/2" HS.
A22: From | C22: To | E22: hrs | G22: Main Phase | I22: Code | K22: Sub Code | M22: Status | P22: NPT/ Unplan Attributed | S22: Rig Activity | AN22: Gain/Loss BPH | AR22: Measure Depth (m) | AU22: Time Break Down
AN23: Type | AP23: MIN | AQ23: MAX | AU23: no | BA23: hrs
A24: 0 | C24: 0.25 | E24: =IF((MOD(C24,1)-MOD(A24,1))*86400/3600>0,(MOD(C24,1)-MOD(A24,1))*86400/3600, IF((MOD(C24,1)-MOD(A24,1))*86400/3600<0,(MOD(C24,1)-MOD(A24,1))*86400/3600+24,"")) -> 6 | G24: DRL | I24: 2 | K24: 1 | M24: PLN | S24: Cont. Drlg 17-1/2" HS f/ 155 to 165m; NL. Due to Obs. SPP Drop gradually 100 psi. Check surface line & MPs; Ok. Decided to POOH to surface. | AU24: 1 | AV24: Rig Up/ Tear Down / Move | BA24: =IF(SUMIF($I$24:$J$61,AU24,$E$24:$F$61)=0,"",SUMIF($I$24:$J$61,AU24,$E$24:$F$61))
E25: =IF((MOD(C25,1)-MOD(A25,1))*86400/3600>0,(MOD(C25,1)-MOD(A25,1))*86400/3600, IF((MOD(C25,1)-MOD(A25,1))*86400/3600<0,(MOD(C25,1)-MOD(A25,1))*86400/3600+24,"")) | S25: Drlg Parameters: WOB: 5-10 klbs, Rot: 70-80 RPM, TQ: 1-1.5 klb.ft, F.R: 550-600GPM, SPP: 500-600psi, On BTM ROP: 2-4 MPH. | AU25: =AU24+1 -> 2 | AV25: Drilling | BA25: =IF(SUMIF($I$24:$J$61,AU25,$E$24:$F$61)=0,"",SUMIF($I$24:$J$61,AU25,$E$24:$F$61)) -> 15
A26: 0.25 | C26: 0.33333333 | E26: =IF((MOD(C26,1)-MOD(A26,1))*86400/3600>0,(MOD(C26,1)-MOD(A26,1))*86400/3600, IF((MOD(C26,1)-MOD(A26,1))*86400/3600<0,(MOD(C26,1)-MOD(A26,1))*86400/3600+24,"")) -> 2 | G26: DRL | I26: 6 | K26: 6 | M26: PLN | S26: POOH w/ 17-1/2" MT Bit to surface. Obs. 2 No. of NZL Seat area washed out. Check another NZL; OK. (Bit Dull Grading: 1-1-WT-A-E-I-WO-BHA) | AU26: =AU25+1 -> 3 | AV26: Reaming | BA26: =IF(SUMIF($I$24:$J$61,AU26,$E$24:$F$61)=0,"",SUMIF($I$24:$J$61,AU26,$E$24:$F$61)) -> 1
A27: 0.33333333 | C27: 0.58333333 | E27: =IF((MOD(C27,1)-MOD(A27,1))*86400/3600>0,(MOD(C27,1)-MOD(A27,1))*86400/3600, IF((MOD(C27,1)-MOD(A27,1))*86400/3600<0,(MOD(C27,1)-MOD(A27,1))*86400/3600+24,"")) -> 6 | G27: DRL | I27: 6 | K27: 2 | M27: PLN | S27: P/U & M/U 17-1/2" Bit (King dream, Used, 1X18/32" + 2 X Open NZL), 2 Jts 9-1/2" DC + 17-1/2" S.Stab (1/8" U.G) + 4 Jt 9-1/2" DC + X.O.S + | AU27: =AU26+1 -> 4 | AV27: Coring | BA27: =IF(SUMIF($I$24:$J$61,AU27,$E$24:$F$61)=0,"",SUMIF($I$24:$J$61,AU27,$E$24:$F$61))
E28: =IF((MOD(C28,1)-MOD(A28,1))*86400/3600>0,(MOD(C28,1)-MOD(A28,1))*86400/3600, IF((MOD(C28,1)-MOD(A28,1))*86400/3600<0,(MOD(C28,1)-MOD(A28,1))*86400/3600+24,"")) | S28: 6 Jt 8-1/2" DC + 3 Jt 5" HWDP (Jt by Jt) & Followed By 5" DP to 165m. | AU28: =AU27+1 -> 5 | AV28: Circulate & Condition | BA28: =IF(SUMIF($I$24:$J$61,AU28,$E$24:$F$61)=0,"",SUMIF($I$24:$J$61,AU28,$E$24:$F$61))
A29: 0.58333333 | C29: 0.89583333 | E29: =IF((MOD(C29,1)-MOD(A29,1))*86400/3600>0,(MOD(C29,1)-MOD(A29,1))*86400/3600, IF((MOD(C29,1)-MOD(A29,1))*86400/3600<0,(MOD(C29,1)-MOD(A29,1))*86400/3600+24,"")) -> 7.5 | G29: DRL | I29: 2 | K29: 1 | M29: PLN | S29: Commence Drlg 17-1/2" H.S f/ 165 to 192m, meanwhile apply limited parameters until S.Stab pass 20" Shoe; NL. | AU29: =AU28+1 -> 6 | AV29: Trips | BA29: =IF(SUMIF($I$24:$J$61,AU29,$E$24:$F$61)=0,"",SUMIF($I$24:$J$61,AU29,$E$24:$F$61)) -> 8
A30: 0.89583333 | C30: 0.91666667 | E30: =IF((MOD(C30,1)-MOD(A30,1))*86400/3600>0,(MOD(C30,1)-MOD(A30,1))*86400/3600, IF((MOD(C30,1)-MOD(A30,1))*86400/3600<0,(MOD(C30,1)-MOD(A30,1))*86400/3600+24,"")) -> 0.5 | G30: DRL | I30: 3 | K30: 1 | M30: PLN | S30: B/R & R/D last drilled Std. | AU30: =AU29+1 -> 7 | AV30: Service/ Maintain Rig | BA30: =IF(SUMIF($I$24:$J$61,AU30,$E$24:$F$61)=0,"",SUMIF($I$24:$J$61,AU30,$E$24:$F$61))
A31: 0.91666667 | C31: 0.97916667 | E31: =IF((MOD(C31,1)-MOD(A31,1))*86400/3600>0,(MOD(C31,1)-MOD(A31,1))*86400/3600, IF((MOD(C31,1)-MOD(A31,1))*86400/3600<0,(MOD(C31,1)-MOD(A31,1))*86400/3600+24,"")) -> 1.5 | G31: DRL | I31: 2 | K31: 1 | M31: PLN | S31: Cont. Drlg 17-1/2" HS to 225m; NL. Pump Bentonite Hi-Vis Pill to sweep hole periodically. | AU31: =AU30+1 -> 8 | AV31: Repair Rig | BA31: =IF(SUMIF($I$24:$J$61,AU31,$E$24:$F$61)=0,"",SUMIF($I$24:$J$61,AU31,$E$24:$F$61))
A32: 0.97916667 | C32: 1 | E32: =IF((MOD(C32,1)-MOD(A32,1))*86400/3600>0,(MOD(C32,1)-MOD(A32,1))*86400/3600, IF((MOD(C32,1)-MOD(A32,1))*86400/3600<0,(MOD(C32,1)-MOD(A32,1))*86400/3600+24,"")) -> 0.5 | G32: DRL | I32: 3 | K32: 1 | M32: PLN | S32: B/R & R/D last drilled Std. | AU32: =AU31+1 -> 9 | AV32: Replacing Drill Line | BA32: =IF(SUMIF($I$24:$J$61,AU32,$E$24:$F$61)=0,"",SUMIF($I$24:$J$61,AU32,$E$24:$F$61))
E33: =IF((MOD(C33,1)-MOD(A33,1))*86400/3600>0,(MOD(C33,1)-MOD(A33,1))*86400/3600, IF((MOD(C33,1)-MOD(A33,1))*86400/3600<0,(MOD(C33,1)-MOD(A33,1))*86400/3600+24,"")) | S33: Drlg. Parameters: WOB: 10-25klb, Rot:80-120 RPM, TQ: 2-4 Klb.ft, F.R:700-900 GPM, SPP: 350-600psi, ROP: 2-20 MPH | AU33: =AU32+1 -> 10 | AV33: Deviation Survey | BA33: =IF(SUMIF($I$24:$J$61,AU33,$E$24:$F$61)=0,"",SUMIF($I$24:$J$61,AU33,$E$24:$F$61))
E34: =IF((MOD(C34,1)-MOD(A34,1))*86400/3600>0,(MOD(C34,1)-MOD(A34,1))*86400/3600, IF((MOD(C34,1)-MOD(A34,1))*86400/3600<0,(MOD(C34,1)-MOD(A34,1))*86400/3600+24,"")) | AU34: =AU33+1 -> 11 | AV34: Logging | BA34: =IF(SUMIF($I$24:$J$61,AU34,$E$24:$F$61)=0,"",SUMIF($I$24:$J$61,AU34,$E$24:$F$61))
E35: =IF((MOD(C35,1)-MOD(A35,1))*86400/3600>0,(MOD(C35,1)-MOD(A35,1))*86400/3600, IF((MOD(C35,1)-MOD(A35,1))*86400/3600<0,(MOD(C35,1)-MOD(A35,1))*86400/3600+24,"")) | AU35: =AU34+1 -> 12 | AV35: Run Casing/ Liner | BA35: =IF(SUMIF($I$24:$J$61,AU35,$E$24:$F$61)=0,"",SUMIF($I$24:$J$61,AU35,$E$24:$F$61))
E36: =IF((MOD(C36,1)-MOD(A36,1))*86400/3600>0,(MOD(C36,1)-MOD(A36,1))*86400/3600, IF((MOD(C36,1)-MOD(A36,1))*86400/3600<0,(MOD(C36,1)-MOD(A36,1))*86400/3600+24,"")) | AU36: =AU35+1 -> 13 | AV36: Cementing | BA36: =IF(SUMIF($I$24:$J$61,AU36,$E$24:$F$61)=0,"",SUMIF($I$24:$J$61,AU36,$E$24:$F$61))
E37: =IF((MOD(C37,1)-MOD(A37,1))*86400/3600>0,(MOD(C37,1)-MOD(A37,1))*86400/3600, IF((MOD(C37,1)-MOD(A37,1))*86400/3600<0,(MOD(C37,1)-MOD(A37,1))*86400/3600+24,"")) | AU37: =AU36+1 -> 14 | AV37: Wait on Cement | BA37: =IF(SUMIF($I$24:$J$61,AU37,$E$24:$F$61)=0,"",SUMIF($I$24:$J$61,AU37,$E$24:$F$61))
E38: =IF((MOD(C38,1)-MOD(A38,1))*86400/3600>0,(MOD(C38,1)-MOD(A38,1))*86400/3600, IF((MOD(C38,1)-MOD(A38,1))*86400/3600<0,(MOD(C38,1)-MOD(A38,1))*86400/3600+24,"")) | AU38: =AU37+1 -> 15 | AV38: Rig Up/Down BOP | BA38: =IF(SUMIF($I$24:$J$61,AU38,$E$24:$F$61)=0,"",SUMIF($I$24:$J$61,AU38,$E$24:$F$61))
E39: =IF((MOD(C39,1)-MOD(A39,1))*86400/3600>0,(MOD(C39,1)-MOD(A39,1))*86400/3600, IF((MOD(C39,1)-MOD(A39,1))*86400/3600<0,(MOD(C39,1)-MOD(A39,1))*86400/3600+24,"")) | AU39: =AU38+1 -> 16 | AV39: Test BOP | BA39: =IF(SUMIF($I$24:$J$61,AU39,$E$24:$F$61)=0,"",SUMIF($I$24:$J$61,AU39,$E$24:$F$61))
E40: =IF((MOD(C40,1)-MOD(A40,1))*86400/3600>0,(MOD(C40,1)-MOD(A40,1))*86400/3600, IF((MOD(C40,1)-MOD(A40,1))*86400/3600<0,(MOD(C40,1)-MOD(A40,1))*86400/3600+24,"")) | AU40: =AU39+1 -> 17 | AV40: Drill Stem Test | BA40: =IF(SUMIF($I$24:$J$61,AU40,$E$24:$F$61)=0,"",SUMIF($I$24:$J$61,AU40,$E$24:$F$61))
E41: =IF((MOD(C41,1)-MOD(A41,1))*86400/3600>0,(MOD(C41,1)-MOD(A41,1))*86400/3600, IF((MOD(C41,1)-MOD(A41,1))*86400/3600<0,(MOD(C41,1)-MOD(A41,1))*86400/3600+24,"")) | AU41: =AU40+1 -> 18 | AV41: Fishing | BA41: =IF(SUMIF($I$24:$J$61,AU41,$E$24:$F$61)=0,"",SUMIF($I$24:$J$61,AU41,$E$24:$F$61))
E42: =IF((MOD(C42,1)-MOD(A42,1))*86400/3600>0,(MOD(C42,1)-MOD(A42,1))*86400/3600, IF((MOD(C42,1)-MOD(A42,1))*86400/3600<0,(MOD(C42,1)-MOD(A42,1))*86400/3600+24,"")) | AU42: =AU41+1 -> 19 | AV42: Specialized Directional Work | BA42: =IF(SUMIF($I$24:$J$61,AU42,$E$24:$F$61)=0,"",SUMIF($I$24:$J$61,AU42,$E$24:$F$61))
E43: =IF((MOD(C43,1)-MOD(A43,1))*86400/3600>0,(MOD(C43,1)-MOD(A43,1))*86400/3600, IF((MOD(C43,1)-MOD(A43,1))*86400/3600<0,(MOD(C43,1)-MOD(A43,1))*86400/3600+24,"")) | AU43: =AU42+1 -> 20 | AV43: Operation Status (Waiting) | BA43: =IF(SUMIF($I$24:$J$61,AU43,$E$24:$F$61)=0,"",SUMIF($I$24:$J$61,AU43,$E$24:$F$61))
E44: =IF((MOD(C44,1)-MOD(A44,1))*86400/3600>0,(MOD(C44,1)-MOD(A44,1))*86400/3600, IF((MOD(C44,1)-MOD(A44,1))*86400/3600<0,(MOD(C44,1)-MOD(A44,1))*86400/3600+24,"")) | AU44: =AU43+1 -> 21 | AV44: Safety | BA44: =IF(SUMIF($I$24:$J$61,AU44,$E$24:$F$61)=0,"",SUMIF($I$24:$J$61,AU44,$E$24:$F$61))
...

Sheet DDR Data
C3: Daily Drilling Report | AQ3: 467
C4: ='DDR Remark'!AG4 -> OEOC 208 | AQ4: 6.25
AQ5: 7
B6: Well Name | E6: ='DDR Remark'!W3 -> AZNS-207 | F6: Report Date | G6: year | H6: month | I6: day | J6: MUD Data | N6: Mud Chemical
B7: Report No | E7: ='DDR Remark'!AQ5 -> 8 | G7: ='DDR Remark'!F11 -> 2024 | H7: ='DDR Remark'!H11 -> Oct | I7: ='DDR Remark'!J11 -> 22 | J7: Report Time | L7: 0 | N7: Product Type | P7: Used | Q7: Received | S7: On Hand | T7: Unit
B8: Drilling Data | J8: Mud Type | L8: Ben. Mud | N8: Bentonite | S8: 13 | T8: 1 MT/BB
B9: Bit No. | E9: 2 | J9: Mud Weight | K9: Unit | L9: 71 | N9: Barite | Q9: 24 | S9: 45 | T9: 1.5 MT/BB
B10: Bit Rerun NO (First Run=0) | E10: 1 | K10: PCF | N10: Limestone | T10: 1MT/BB
B11: Bit Size (inch) | E11: 17-1/2" | J11: Funnel Vis (Sec/QT) | L11: 33 | N11: Salt | P11: 20 | S11: 81 | T11: 1 MT/BB
B12: Bit Type | E12: MT Bit (GAT135G) | J12: PV (CP) | L12: 7 | N12: Lime | P12: 17 | R12: =R10-R9 -> 0 | S12: 163 | T12: 25 KG/SX
B13: Bit Manufacture | E13: KingDream | J13: YP (lb/100ft2) | L13: 15 | N13: API Starch | Q13: 40 | S13: 160 | T13: 25 KG/SX
B14: Bit Serial No. | J14: Gel 10 s (lb/100ft2) | L14: 4 | N14: Caustic Soda | P14: 3 | Q14: 40 | S14: 54 | T14: 25 KG/SX
B15: IADC Code | E15: 135 | J15: Gel 10 min (lb/100ft2) | L15: 6 | N15: Soda Ash | Q15: 40 | S15: 58 | T15: 25 KG/SX
B16: Bit Nozzle | E16: Nozzle No | F16: Nozzle size (1/32 inch) | G16: Nozzle No | I16: Nozzle size (1/32 inch) | J16: API Fluid Loss (cc/30 min) | L16: N.C | N16: Xanthan Gum | S16: 25 | T16: 25 KG/SX
E17: 1 | F17: 18/32" | J17: Total Hardness (mg/lit) | L17: 400 | N17: Nut Plug (C) | S17: 40 | T17: 25 KG/SX
J18: Filter Cake (1/32") | N18: Nut Plug (M) | T18: 25 KG/SX
E19: 2 | F19: Open | J19: Solid (% Vol) | L19: 7 | N19: Nut Plug (F) | T19: 25 KG/SX
J20: Chloride (mg/lit) | L20: 7400 | N20: Oyster Shell (C) | T20: 25 KG/SX
J21: Oil / Water (% Vol) | L21: 5 | N21: Oyster Shell (M) | T21: 25 KG/SX
J22: KCL (% wt) | N22: Oyster Shell (F) | T22: 25 KG/SX
J23: PH | L23: 10.5 | N23: Limestone chips(M) | T23: 25 KG/SX
J24: Flowline Temp (°F) | N24: Limestone chips(C) | T24: 25 KG/SX
B25: TFA ( in^2) | E25: 4.32 | J25: Pf / Mf | N25: Limestone chips(F) | T25: 25 KG/SX
J26: Ca++ (mg/lit) | L26: 320 | N26: Mica (F) | T26: 25 KG/SX
B27: Bit Drilled (m) | E27: 70 | J27: MBT (lb/bbl) | N27: Mica (M) | T27: 25 KG/SX
B28: Bit Cum. Drilled (m) | E28: 76 | N28: Mica (C) | S28: 80 | T28: 25 KG/SX
B29: Bit Hours on Bottom | E29: 8.5 | N29: Sodium Bicarbonate | T29: 50 KG/SX
B30: Bit Cum. Hrs on Bottom | E30: 14 | N30: Anti-Foam | T30: 55 GAL/DM
B31: Cum.Bit Ave ROP (m/hr) | E31: =E28/E30 -> 5.4285714 | N31: H2S Scavenger | T31: 55 GAL/DM
B32: Bit Dull Condition | N32: Citric Acid | T32: 25 KG/SX
B33: Bit revolution (k.rev) | E33: 60 | J33: Vol. Info | N33: Biocide | T33: 55 GAL/DM
B34: Pump Liner Size (inch) | E34: P#1 : (180mm x 12") + P#2 : (180mm x 12") + P#3 : (180mm x 12") | J34: Vol. in Hole (bbls) | L34: 218 | N34: KCl | S34: 12 | T34: 1MT/BB
B35: Pump Output (gpm) | E35: min | F35: max | G35: min | I35: max | J35: Total Cir. Volume (bbls) | L35: 758 | N35: Corrosion Inhibitor | T35: 55 GAL/DM
E36: 700 | F36: 900 | J36: Mud Lost Down Hole (bbls) | N36: Oxygen Scavenger | T36: 55 GAL/DM
B37: Drilling Parameter | E37: min | F37: max | G37: min | I37: max | J37: Mud Lost at Surface (bbls) | L37: 158 | N37: Pipe Lax | T37: 55 GAL/DM
B38: W.O.B (klb) | E38: 10 | F38: 30 | J38: Suction 1 Vol.(bbls)/MW (PCF) | L38: 270 | M38: 71 | N38: Bit Lube | T38: 55 GAL/DM
B39: Motor RPM ( rev/gal) | J39: Suction 2 Vol.(bbls)/MW (PCF) | L39: 330 | M39: 72 | N39: Drilling Detergent | T39: 55 GAL/DM
B40: Surf. RPM ( rev/gal) | E40: 80 | F40: 120 | J40: Reserve 1 Vol.(bbls)/MW (PCF) | L40: 190 | M40: 70 | N40: Glass Bead (M) | T40: 25 KG/SX
B41: Torque (kft-lbs) | E41: 2 | F41: 4 | J41: Reserve 2 Vol.(bbls)/MW (PCF) | L41: 45 | M41: 70 | N41: Kwick Seal (M) | S41: 80 | T41: 25 KG/SX
B42: Pump Pressure (psi) | E42: 350 | F42: 600 | J42: Reserve 3 Vol.(bbls)/MW (PCF) | L42: 90 | M42: 62
...

Sheet Lookahead
A1: Operations Lookahead - Rig Name OEOC 208 Well Name AZNS 207, F-20
A5: SPUD THE RIG @ 15-Oct-2024, 18:00 | S5: 45587
A7: Days | B7: Activity | N7: Comments
J9: HRs | L9: Date Start | M9: Date End
A10: =L10 -> 45587 | B10: Drilling 17-1/2" HS to 165m. CBU & POOH to surface. | J10: 14 | L10: =S5 -> 45587 | M10: =L10+J10/24 -> 45587.583
A11: =L11 -> 45587.583 | B11: RIH w/ same bit and S.Stab @ 20m to bottom & Resume Drlg 17-1/2'' HS to 220m. | J11: 10 | L11: =M10 -> 45587.583 | M11: =L11+J11/24 -> 45588
A12: =L12 -> 45588 | B12: Cont. Drlg 17-1/2'' HS to 450m. | J12: 19 | L12: =M11 -> 45588 | M12: =L12+J12/24 -> 45588.792
A13: =L13 -> 45588.792 | B13: CBU, Take Survey. | J13: 3 | L13: =M12 -> 45588.792 | M13: =L13+J13/24 -> 45588.917
A14: =L14 -> 45588.917 | B14: Perform wiper trip. | J14: 2 | L14: =M13 -> 45588.917 | M14: =L14+J14/24 -> 45589
A15: =L15 -> 45589 | B15: Cont. Drlg 17-1/2'' HS to 600m. | J15: 24 | L15: =M14 -> 45589 | M15: =L15+J15/24 -> 45590
A16: =L16 -> 45590 | B16: Cont. Drlg 17-1/2'' HS to 750m. | J16: 8 | L16: =M15 -> 45590 | M16: =L16+J16/24 -> 45590.333
A17: =L17 -> 45590.333 | B17: CBU, Take Survey. | J17: 4 | L17: =M16 -> 45590.333 | M17: =L17+J17/24 -> 45590.5
A18: =L18 -> 45590.5 | B18: Perform wiper trip. | J18: 2 | L18: =M17 -> 45590.5 | M18: =L18+J18/24 -> 45590.583
A19: =L19 -> 45590.583 | B19: Displace mud in hole by 72pcf KCL/Polymer mud @ 750m | J19: 2 | L19: =M18 -> 45590.583 | M19: =L19+J19/24 -> 45590.667
A20: =L20 -> 45590.667 | B20: Cont. Drlg 17-1/2'' HS to 800m. | J20: 8 | L20: =M19 -> 45590.667 | M20: =L20+J20/24 -> 45591
A21: =L21 -> 45591 | J21: 24 | L21: =M20 -> 45591 | M21: =L21+J21/24 -> 45592
A22: =L22 -> 45592 | J22: 24 | L22: =M21 -> 45592 | M22: =L22+J22/24 -> 45593
A24: Equipment To Be Sent Back: | F24: 6" M.M J.Mill, 4-1/4" Taper Tap, 8-3/8" M.M.J.Mill, 8-1/2" Bit, 6-1/8" Bit, 5-7/8" Bit, 4-1/2" TP-G2 Pin X 4-1/2" IF box, 7" Circ. Swage, 7" & 4-1/2" Drift, 4-1/2" X 6-1/8" Spirolizer, 7" X 8-1/2" Spirolizer, 4 Jts 20" CSG.
A25: Request: | F25: Needle valve and Press. gauge for Section "A" & "B".
A26: Prepared By: | F26: ='DDR Remark'!AB12 -> A.Eyvazi | M26: Approved By: | P26: ='DDR Remark'!AB11 -> A.Seifi

Sheet Service Company
A1: Hole Section | B1: Company | C1: Service | D1: Date In | E1: Date Out | F1: Duration (Day) | G1: Job Description | H1: Condition | I1: Problem/Issue | J1: Total NPT (HRS)
A2: 26" HS | B2: Vira | C2: Mud Service | D2: Spud 15-Oct-2024
A3: 26" HS | B3: APAD | C3: Waste Management Service | D3: Spud 15-Oct-2024 | AQ3: 467
A4: 26" | B4: GEO Data | C4: Mud Logging Service | D4: Spud 15-Oct-2024 | AQ4: 6.25
A5: 26" HS | B5: OEOC | C5: CSG Running Service | D5: 18-Oct-2024, 18:00. | E5: 19-Oct-2024, 18:00 | F5: 1 | G5: Run 20" CSG | AQ5: 7
A6: 26" HS | B6: SPAD Energy | C6: CMT Service | D6: 19-Oct-2024, 08:00. | E6: 19-Oct-2024, 20:00 | F6: 1 | G6: CMT 20" CSG
A7: 26" HS | B7: OEOC | C7: Wellhead Crew | D7: 19-Oct-2024, 11:00. | E7: 20-Oct-2024, 13:30 | F7: 3 | G7: Install & P.T 20-3/4" C.H.H
R12: =R10-R9 -> 0
S25: Landing Jt. L/D mouse hole. Cut & L/D 30" conductor pipe. Install Base Plate & Welded same to 20" CSG. Final Cut 20" CSG, Dress & Bevel
S27: N/U 20-3/4" BOP Stack as: 20-3/4" 3k X 3k DSA + Spacer Spool + Drlg spool + Double Rams (Blind Rams, 5" Fix Rams) + Ann Preventer.
A82: Note#02 : Due to sever power surges on 16-Oct-2024, some electrical appliances of mudlogging service got damaged (1No. 21" monitor, 2No. Case power, 1No. Motherboard, 1No. POE access point).

Sheet Activity Codes
B2: Main Phase | D2: Description
B3: MOV | C3: Moving | D3: All of operation from Tear out, Rig down, …, Transportation to Rig up & Spud. | AO3: 467
B4: DRL | C4: Drilling | D4: All of operation during making a hole from surface to the target including Trips, Circulation, Drilling, Reaming, etc. | AO4: 6.25
B5: LOG | C5: Logging | D5: All of operation during taking a log from R/U logging Equip. to R/D including all of related activities same as Logging, Condition trip, Fishing, etc. | S5: NI-015 | AO5: 7
B6: CSG | C6: Casing/ Liner | D6: Includes all procedures from Rig up Running Equipment, Casing/ Liner Running, Perform CMT job and R/D same. | S6: 44284 | X6: M1
B7: COM | C7: Completion | D7: Includes all procedures from Rig up Running Equipment, Running Completion String, Pressure Tests, Instaling XMT and Perforation Job.
B8: FTS | C8: Formation Testing & Stimulation | D8: All of operation related to Acidizing, Testing, Lifting, Well Flowing, etc.
B9: PIH | C9: Pilot Hole | D9: Drilling a small hole diameter into the formation including all related operation same as Time drilling, Logging, Coring, Plug back, etc.
B10: COR | C10: Coring | D10: The extraction from the wellbore of a cylindrical sample for geological analysis.
B11: REE | C11: Re-Entry | D11: The act of entering a plugged well for the purpose of utilizing said well for the production of oil or gas, for the disposal of fluids therein, for a service well, or for the salvaging of tubing or casing therefrom.
B12: ABD | C12: Abandonment/Suspension | D12: Including all operation to permanent or temporarily subsurface isolation to prevent any undesired communication between any distinct zones and fluid movement out of a well using validated well barriers. | P12: =P10-P9 -> 0
A14: Code | B14: Sub code | C14: Code Name | D14: Description
A15: 1 | C15: Rig Up/ Tear Down / Move
B16: 1-1 | C16: Rig Moving/ Positioning | D16: Rig Moving, Spot, Positioning and verify the location.
B17: 1-2 | C17: Rig Up | D17: The on-site connection of rig components in preparation for drilling or well servicing operations. Rig up begins when the first rig components have arrived at the wellsite, and ends when the rig is ready to spud the well.
B18: 1-3 | C18: Rig Down | D18: To take apart equipment for storage and portability.
B19: 1-4 | C19: Tear Out | D19: The act of dismantling a rig at the end of a well and preparing it for moving to the next location.
B20: 1-5 | C20: Rig Skid | D20: Skid in /out Activities.
A21: 2 | C21: Drilling
B22: 2-1 | C22: Vertical Drilling | D22: Vertical Drilling, with all type of BHA with or without DHM (Performane Drilling )
B23: 2-2 | C23: Directional & Horizontal Drlg. (Rotating mode) | D23: Any Directional Drilling at Rotating Mode with Directional BHA
B24: 2-3 | C24: Directional & Horizontal Drlg. (Sliding mode) | D24: Any Directional Drilling at Sliding Mode
B25: 2-4 | C25: Coiled Tubing Drilling | D25: Drilling Formation with CT. | Q25: Landing Jt. L/D mouse hole. Cut & L/D 30" conductor pipe. Install Base Plate & Welded same to 20" CSG. Final Cut 20" CSG, Dress & Bevel
A26: 3 | C26: Reaming
B27: 3-1 | C27: Reaming / Back Reaming | D27: Any Rotating of Bit Without Making Hole. | Q27: N/U 20-3/4" BOP Stack as: 20-3/4" 3k X 3k DSA + Spacer Spool + Drlg spool + Double Rams (Blind Rams, 5" Fix Rams) + Ann Preventer.
B28: 3-2 | C28: Wash Down | D28: Run in Hole With Pumping
B29: 3-3 | C29: Under reaming/ Hole Opening/ Hole Enlargement | D29: Planned Opening Hole/Underreaming/ Hole Enlargment
B30: 3-4 | C30: Drill Out Cement/ Shoe track | D30: Any Vertical or Directional Drilling of Cement, Float and shoe
A31: 4 | C31: Coring
B32: 4-1 | C32: Trip in for Coring | D32: P/U & M/U Equip. RIH for Coring Operation
B33: 4-2 | C33: Trip out for Coring | D33: POOH for Coring Operation, B/O & L/D Equip.
B34: 4-3 | C34: Coring Operation | D34: Coring operation and any circulating.
B35: 4-4 | C35: Core Recovery | D35: Core Recovery Period time
A36: 5 | C36: Circulate & Condition
B37: 5-1 | C37: Hole displacement | D37: Mud Preparation, Displacing the hole with mud or any fluid
B38: 5-2 | C38: Circulate/ Condition Mud | D38: Sweep the well, Circulation of hole to clean hole, treat the mud condition.
B39: 5-3 | C39: Coiled Tubing Ops. | D39: Circulation of hole with CT
B40: 5-4 | C40: Loss control | D40: All Activities Associated with Circulate and Condition due to lost circulation or putting LCM plugs & CMT plug.
A41: 6 | C41: Trips
B42: 6-1 | C42: R/U & R/D Pipe Handling Equip. | D42: Rig up and Rig down Pipe/BHA Handling Equipment
...

Sheet setting
Q4: DAY | R4: Month | S4: year | T4: Operation type | U4: Drilling Superintendent : | V4: Drilling Supervisor Day: | W4: Drilling Supervisor Night : | X4: Well Site Drilling Engineering: | Y4: Well Site Geologist: | Z4: Rig Operations Manager /Rig Manager: | AA4: Drilling Contractor: | AB4: Tool Pusher Day / Night : | AC4: IADC CODE (BIT) | AD4: Bit Type | AE4: Mud Type
A5: Field | B5: bit size | C5: CASING LINER SIZE | D5: HOLE SECTION | E5: Well Name | F5: status | G5: Rig Name | H5: Project | I5: Service Copmany | J5: GAIN LOS TYPE | K5: MW UNIT | L5: MAIN PHASE | M5: WELL TEYPE | N5: WELL SHAPE | Q5: 1 | R5: Jan | S5: 2021 | T5: Offshore | AC5: M1365 | AD5: Type1 | AE5: Salt-Polymer
A6: Azadegan | B6: 32 | C6: 32 | D6: 32 | E6: NI-015 | F6: PLN | G6: DANA-1 Rig | H6: Belal | J6: GAIN | K6: (pcf)/ @35˚C | L6: MOV | M6: Development | N6: J Shape | Q6: =Q5+1 -> 2 | R6: Feb | S6: 2022 | T6: Onshore | AC6: M1366 | AD6: Type2 | AE6: Brine
A7: Gachsaran | B7: 26 | C7: 26 | D7: 26 | E7: NI-016 | F7: UNPLN | G7: DANA-2 Rig | H7: West Paydar | J7: LOSS | K7: PPG | L7: DRL | Q7: =Q6+1 -> 3 | R7: Mar | S7: =S6+1 -> 2023 | AC7: M1367 | AD7: Type3 | AE7: Kcl
A8: West Paydar | B8: 23 | C8: 23 | D8: 23 | E8: NI-017 | F8: NPT | G8: DANA-3 Rig | H8: Gachsaran 3&4 | L8: LOG | Q8: =Q7+1 -> 4 | R8: Apr | S8: =S7+1 -> 2024 | AC8: M1368 | AD8: Type4 | AE8: KCL-Polymer
A9: Ramin | B9: 17.333333 | C9: 17.333333 | D9: 17.333333 | E9: NI-018 | F9: NPT-UNPLN | H9: Azadegan | L9: CSG | Q9: =Q8+1 -> 5 | R9: May | S9: =S8+1 -> 2025 | AC9: M1369 | AD9: Type5
A10: Ahwaz | B10: 13.375 | C10: 13.375 | D10: 13.375 | E10: NI-019 | L10: COM | Q10: =Q9+1 -> 6 | R10: Jun | S10: =S9+1 -> 2026 | AC10: M1370 | AD10: Type6
A11: Farzad | B11: 12.25 | C11: 12.25 | D11: 12.25 | E11: NI-020 | L11: FTS | Q11: =Q10+1 -> 7 | R11: Jul | S11: =S10+1 -> 2027 | AC11: M1371 | AD11: Type7
A12: Nargesi | B12: 6 | C12: 6 | D12: 6 | E12: NI-021 | L12: PIH | Q12: =Q11+1 -> 8 | R12: Aug | S12: =S11+1 -> 2028 | AC12: M1372 | AD12: Type8
E13: NI-022 | L13: COR | Q13: =Q12+1 -> 9 | R13: Sep | S13: =S12+1 -> 2029 | AC13: M1373 | AD13: Type9
E14: NI-023 | L14: REE | Q14: =Q13+1 -> 10 | R14: Oct | S14: =S13+1 -> 2030 | AC14: M1374 | AD14: Type10
E15: NI-024 | L15: ABD | Q15: =Q14+1 -> 11 | R15: Nov | S15: =S14+1 -> 2031 | AC15: M1375 | AD15: Type11
E16: NI-025 | Q16: =Q15+1 -> 12 | R16: Dec | S16: =S15+1 -> 2032 | AC16: M1376 | AD16: Type12
E17: NI-026 | Q17: =Q16+1 -> 13 | S17: =S16+1 -> 2033 | AC17: M1377 | AD17: Type13
E18: NI-027 | Q18: =Q17+1 -> 14 | S18: =S17+1 -> 2034 | AC18: M1378 | AD18: Type14
E19: NI-028 | Q19: =Q18+1 -> 15 | S19: =S18+1 -> 2035 | AC19: M1379 | AD19: Type15
E20: NI-029 | Q20: =Q19+1 -> 16 | S20: =S19+1 -> 2036 | AC20: M1380 | AD20: Type16
E21: NI-030 | Q21: =Q20+1 -> 17 | S21: =S20+1 -> 2037 | AC21: M1381 | AD21: Type17
E22: NI-031 | Q22: =Q21+1 -> 18 | S22: =S21+1 -> 2038 | AD22: Type18
E23: NI-032 | Q23: =Q22+1 -> 19 | S23: =S22+1 -> 2039 | AD23: Type19
E24: NI-033 | Q24: =Q23+1 -> 20 | S24: =S23+1 -> 2040 | AD24: Type20
E25: NI-034 | Q25: =Q24+1 -> 21 | S25: =S24+1 -> 2041 | AD25: Type21
E26: NI-035 | Q26: =Q25+1 -> 22 | S26: =S25+1 -> 2042 | AD26: Type22
E27: NI-036 | Q27: =Q26+1 -> 23 | S27: =S26+1 -> 2043 | AD27: Type23
E28: NI-037 | Q28: =Q27+1 -> 24 | S28: =S27+1 -> 2044 | AD28: Type24
E29: NI-038 | Q29: =Q28+1 -> 25 | S29: =S28+1 -> 2045 | AD29: Type25
E30: NI-039 | Q30: =Q29+1 -> 26 | S30: =S29+1 -> 2046 | AD30: Type26
E31: NI-040 | Q31: =Q30+1 -> 27 | S31: =S30+1 -> 2047 | AD31: Type27
E32: NI-041 | Q32: =Q31+1 -> 28 | S32: =S31+1 -> 2048 | AD32: Type28
E33: NI-042 | Q33: =Q32+1 -> 29 | S33: =S32+1 -> 2049 | AD33: Type29
E34: NI-043 | Q34: =Q33+1 -> 30 | S34: =S33+1 -> 2050 | AD34: Type30
Q35: =Q34+1 -> 31 | AD35: Type31
AD36: Type32
AD37: Type33
AD38: Type34
AD39: Type35
AD40: Type36
AD41: Type37
AD42: Type38
AD43: Type39
...
